Workbook

Sheet Overview
A1: Sales Funnel Analytics
A2: Key metrics computed live from the Data sheet - change a row there and these update.
A4: Total Leads | B4: Win Rate | C4: Revenue Won | D4: Avg Deal Size
A5: =COUNTA(Data!$A$2:$A$7001) | B5: =ROUND(COUNTIF(Data!$I$2:$I$7001,"Won")/A5,3) | C5: =ROUND(SUMIFS(Data!$K$2:$K$7001,Data!$I$2:$I$7001,"Won"),2) | D5: =ROUND(AVERAGEIFS(Data!$K$2:$K$7001,Data!$I$2:$I$7001,"Won"),2)
A7: Top Source by Win Rate | C7: Top Lost Reason by Value | E7: Top Rep by Revenue
A8: =INDEX('Win Rate by Source'!A2:A8,MATCH(MAX('Win Rate by Source'!D2:D8),'Win Rate by Source'!D2:D8,0)) | C8: =INDEX('Lost Value by Reason'!A2:A6,MATCH(MAX('Lost Value by Reason'!C2:C6),'Lost Value by Reason'!C2:C6,0)) | E8: =INDEX('Rep Leaderboard'!A2:A16,MATCH(MAX('Rep Leaderboard'!E2:E16),'Rep Leaderboard'!E2:E16,0))
A10: Top Funnel Drop-off Stage (biggest % lost vs. previous stage)
A11: See the Funnel sheet - stage-by-stage percentages are listed there.

Sheet Data
A1: lead_id | B1: created_at | C1: source | D1: product | E1: region | F1: rep | G1: response_time_hours | H1: stage_reached | I1: status | J1: lost_reason | K1: deal_value | L1: closed_at | M1: stage_num | N1: response_bucket | O1: created_month
A2: LD-300000 | B2: 2025-11-14 14:30:00 | C2: Webinar | D2: Coding for Kids | E2: International | F2: Rep_15 | G2: 0.57 | H2: Closed | I2: Won | K2: 574.72 | L2: 2025-12-15 09:41:11.226466 | M2: =VLOOKUP(H2,'Stage Order'!$A$2:$B$8,2,FALSE) | N2: =IF(G2<=1,"1. Under 1 hour",IF(G2<=24,"2. 1-24 hours",IF(G2<=72,"3. 1-3 days","4. Over 3 days"))) | O2: =TEXT(B2,"YYYY-MM")
A3: LD-300001 | B3: 2026-06-12 16:52:00 | C3: Organic Search | D3: Language Learning | E3: North Region | F3: Rep_01 | G3: 2.72 | H3: Contacted | I3: Open | M3: =VLOOKUP(H3,'Stage Order'!$A$2:$B$8,2,FALSE) | N3: =IF(G3<=1,"1. Under 1 hour",IF(G3<=24,"2. 1-24 hours",IF(G3<=72,"3. 1-3 days","4. Over 3 days"))) | O3: =TEXT(B3,"YYYY-MM")
A4: LD-300002 | B4: 2026-01-21 15:02:00 | C4: Organic Search | D4: Coding for Kids | E4: South Region | F4: Rep_12 | G4: 1.63 | H4: Demo Completed | I4: Lost | J4: Went With Competitor | K4: 673.32 | L4: 2026-02-25 19:23:42.793161 | M4: =VLOOKUP(H4,'Stage Order'!$A$2:$B$8,2,FALSE) | N4: =IF(G4<=1,"1. Under 1 hour",IF(G4<=24,"2. 1-24 hours",IF(G4<=72,"3. 1-3 days","4. Over 3 days"))) | O4: =TEXT(B4,"YYYY-MM")
A5: LD-300003 | B5: 2025-08-28 15:26:00 | C5: Referral | D5: K-12 Math | E5: South Region | F5: Rep_07 | G5: 1.77 | H5: Contacted | I5: Open | M5: =VLOOKUP(H5,'Stage Order'!$A$2:$B$8,2,FALSE) | N5: =IF(G5<=1,"1. Under 1 hour",IF(G5<=24,"2. 1-24 hours",IF(G5<=72,"3. 1-3 days","4. Over 3 days"))) | O5: =TEXT(B5,"YYYY-MM")
A6: LD-300004 | B6: 2026-06-03 10:00:00 | C6: Paid Search | D6: Language Learning | E6: West Region | F6: Rep_13 | G6: 2.73 | H6: Lead | I6: Open | M6: =VLOOKUP(H6,'Stage Order'!$A$2:$B$8,2,FALSE) | N6: =IF(G6<=1,"1. Under 1 hour",IF(G6<=24,"2. 1-24 hours",IF(G6<=72,"3. 1-3 days","4. Over 3 days"))) | O6: =TEXT(B6,"YYYY-MM")
A7: LD-300005 | B7: 2025-09-19 20:36:00 | C7: Organic Search | D7: K-12 Math | E7: International | F7: Rep_15 | G7: 2.29 | H7: Contacted | I7: Open | M7: =VLOOKUP(H7,'Stage Order'!$A$2:$B$8,2,FALSE) | N7: =IF(G7<=1,"1. Under 1 hour",IF(G7<=24,"2. 1-24 hours",IF(G7<=72,"3. 1-3 days","4. Over 3 days"))) | O7: =TEXT(B7,"YYYY-MM")
A8: LD-300006 | B8: 2025-11-14 14:03:00 | C8: Paid Search | D8: K-12 Math | E8: North Region | F8: Rep_06 | G8: 3.21 | H8: Contacted | I8: Open | M8: =VLOOKUP(H8,'Stage Order'!$A$2:$B$8,2,FALSE) | N8: =IF(G8<=1,"1. Under 1 hour",IF(G8<=24,"2. 1-24 hours",IF(G8<=72,"3. 1-3 days","4. Over 3 days"))) | O8: =TEXT(B8,"YYYY-MM")
A9: LD-300007 | B9: 2025-09-01 17:03:00 | C9: Paid Search | D9: K-12 Math | E9: North Region | F9: Rep_01 | G9: 0.48 | H9: Contacted | I9: Open | M9: =VLOOKUP(H9,'Stage Order'!$A$2:$B$8,2,FALSE) | N9: =IF(G9<=1,"1. Under 1 hour",IF(G9<=24,"2. 1-24 hours",IF(G9<=72,"3. 1-3 days","4. Over 3 days"))) | O9: =TEXT(B9,"YYYY-MM")
A10: LD-300008 | B10: 2025-08-25 19:40:00 | C10: Referral | D10: Coding for Kids | E10: South Region | F10: Rep_07 | G10: 2.55 | H10: Closed | I10: Won | K10: 723.67 | L10: 2025-10-16 20:41:44.872095 | M10: =VLOOKUP(H10,'Stage Order'!$A$2:$B$8,2,FALSE) | N10: =IF(G10<=1,"1. Under 1 hour",IF(G10<=24,"2. 1-24 hours",IF(G10<=72,"3. 1-3 days","4. Over 3 days"))) | O10: =TEXT(B10,"YYYY-MM")
A11: LD-300009 | B11: 2026-06-03 14:05:00 | C11: Paid Search | D11: K-12 Math | E11: South Region | F11: Rep_12 | G11: 6.24 | H11: Contacted | I11: Open | M11: =VLOOKUP(H11,'Stage Order'!$A$2:$B$8,2,FALSE) | N11: =IF(G11<=1,"1. Under 1 hour",IF(G11<=24,"2. 1-24 hours",IF(G11<=72,"3. 1-3 days","4. Over 3 days"))) | O11: =TEXT(B11,"YYYY-MM")
A12: LD-300010 | B12: 2026-06-22 11:08:00 | C12: Partner Channel | D12: Competitive Exam Prep | E12: International | F12: Rep_05 | G12: 2.95 | H12: Contacted | I12: Open | M12: =VLOOKUP(H12,'Stage Order'!$A$2:$B$8,2,FALSE) | N12: =IF(G12<=1,"1. Under 1 hour",IF(G12<=24,"2. 1-24 hours",IF(G12<=72,"3. 1-3 days","4. Over 3 days"))) | O12: =TEXT(B12,"YYYY-MM")
A13: LD-300011 | B13: 2025-11-11 15:49:00 | C13: Cold Outreach | D13: Competitive Exam Prep | E13: International | F13: Rep_10 | G13: 1 | H13: Lead | I13: Open | M13: =VLOOKUP(H13,'Stage Order'!$A$2:$B$8,2,FALSE) | N13: =IF(G13<=1,"1. Under 1 hour",IF(G13<=24,"2. 1-24 hours",IF(G13<=72,"3. 1-3 days","4. Over 3 days"))) | O13: =TEXT(B13,"YYYY-MM")
A14: LD-300012 | B14: 2025-03-28 14:32:00 | C14: Webinar | D14: Coding for Kids | E14: West Region | F14: Rep_13 | G14: 3 | H14: Closed | I14: Won | K14: 603.05 | L14: 2025-05-02 11:58:34.056521 | M14: =VLOOKUP(H14,'Stage Order'!$A$2:$B$8,2,FALSE) | N14: =IF(G14<=1,"1. Under 1 hour",IF(G14<=24,"2. 1-24 hours",IF(G14<=72,"3. 1-3 days","4. Over 3 days"))) | O14: =TEXT(B14,"YYYY-MM")
A15: LD-300013 | B15: 2025-03-10 20:45:00 | C15: Referral | D15: Coding for Kids | E15: North Region | F15: Rep_06 | G15: 4.93 | H15: Contacted | I15: Open | M15: =VLOOKUP(H15,'Stage Order'!$A$2:$B$8,2,FALSE) | N15: =IF(G15<=1,"1. Under 1 hour",IF(G15<=24,"2. 1-24 hours",IF(G15<=72,"3. 1-3 days","4. Over 3 days"))) | O15: =TEXT(B15,"YYYY-MM")
A16: LD-300014 | B16: 2026-05-04 17:50:00 | C16: Cold Outreach | D16: Language Learning | E16: East Region | F16: Rep_04 | G16: 2.18 | H16: Lead | I16: Open | M16: =VLOOKUP(H16,'Stage Order'!$A$2:$B$8,2,FALSE) | N16: =IF(G16<=1,"1. Under 1 hour",IF(G16<=24,"2. 1-24 hours",IF(G16<=72,"3. 1-3 days","4. Over 3 days"))) | O16: =TEXT(B16,"YYYY-MM")
A17: LD-300015 | B17: 2025-06-11 07:10:00 | C17: Organic Search | D17: K-12 Math | E17: South Region | F17: Rep_02 | G17: 5.4 | H17: Contacted | I17: Open | M17: =VLOOKUP(H17,'Stage Order'!$A$2:$B$8,2,FALSE) | N17: =IF(G17<=1,"1. Under 1 hour",IF(G17<=24,"2. 1-24 hours",IF(G17<=72,"3. 1-3 days","4. Over 3 days"))) | O17: =TEXT(B17,"YYYY-MM")
A18: LD-300016 | B18: 2025-02-28 09:06:00 | C18: Paid Search | D18: Study Abroad Prep | E18: West Region | F18: Rep_13 | G18: 6.82 | H18: Demo Completed | I18: Lost | J18: No Response / Ghosted | K18: 1379.65 | L18: 2025-03-28 10:20:43.782866 | M18: =VLOOKUP(H18,'Stage Order'!$A$2:$B$8,2,FALSE) | N18: =IF(G18<=1,"1. Under 1 hour",IF(G18<=24,"2. 1-24 hours",IF(G18<=72,"3. 1-3 days","4. Over 3 days"))) | O18: =TEXT(B18,"YYYY-MM")
A19: LD-300017 | B19: 2026-04-04 11:09:00 | C19: Webinar | D19: Competitive Exam Prep | E19: East Region | F19: Rep_04 | G19: 4.1 | H19: Contacted | I19: Open | M19: =VLOOKUP(H19,'Stage Order'!$A$2:$B$8,2,FALSE) | N19: =IF(G19<=1,"1. Under 1 hour",IF(G19<=24,"2. 1-24 hours",IF(G19<=72,"3. 1-3 days","4. Over 3 days"))) | O19: =TEXT(B19,"YYYY-MM")
A20: LD-300018 | B20: 2025-09-29 09:35:00 | C20: Referral | D20: Coding for Kids | E20: North Region | F20: Rep_06 | G20: 5.16 | H20: Contacted | I20: Open | M20: =VLOOKUP(H20,'Stage Order'!$A$2:$B$8,2,FALSE) | N20: =IF(G20<=1,"1. Under 1 hour",IF(G20<=24,"2. 1-24 hours",IF(G20<=72,"3. 1-3 days","4. Over 3 days"))) | O20: =TEXT(B20,"YYYY-MM")
A21: LD-300019 | B21: 2025-07-17 11:05:00 | C21: Cold Outreach | D21: Study Abroad Prep | E21: North Region | F21: Rep_11 | G21: 3.97 | H21: Lead | I21: Open | M21: =VLOOKUP(H21,'Stage Order'!$A$2:$B$8,2,FALSE) | N21: =IF(G21<=1,"1. Under 1 hour",IF(G21<=24,"2. 1-24 hours",IF(G21<=72,"3. 1-3 days","4. Over 3 days"))) | O21: =TEXT(B21,"YYYY-MM")
A22: LD-300020 | B22: 2025-12-27 10:09:00 | C22: Paid Search | D22: K-12 Math | E22: South Region | F22: Rep_07 | G22: 1.97 | H22: Closed | I22: Won | K22: 423.65 | L22: 2026-01-31 19:29:05.287792 | M22: =VLOOKUP(H22,'Stage Order'!$A$2:$B$8,2,FALSE) | N22: =IF(G22<=1,"1. Under 1 hour",IF(G22<=24,"2. 1-24 hours",IF(G22<=72,"3. 1-3 days","4. Over 3 days"))) | O22: =TEXT(B22,"YYYY-MM")
A23: LD-300021 | B23: 2025-07-07 17:46:00 | C23: Paid Search | D23: K-12 Math | E23: East Region | F23: Rep_09 | G23: 3.27 | H23: Demo Completed | I23: Lost | J23: Bad Timing | K23: 491.48 | L23: 2025-07-31 00:34:05.025358 | M23: =VLOOKUP(H23,'Stage Order'!$A$2:$B$8,2,FALSE) | N23: =IF(G23<=1,"1. Under 1 hour",IF(G23<=24,"2. 1-24 hours",IF(G23<=72,"3. 1-3 days","4. Over 3 days"))) | O23: =TEXT(B23,"YYYY-MM")
A24: LD-300022 | B24: 2025-04-09 19:52:00 | C24: Referral | D24: K-12 Math | E24: West Region | F24: Rep_08 | G24: 1.76 | H24: Closed | I24: Won | K24: 443.38 | L24: 2025-05-14 21:34:45.733557 | M24: =VLOOKUP(H24,'Stage Order'!$A$2:$B$8,2,FALSE) | N24: =IF(G24<=1,"1. Under 1 hour",IF(G24<=24,"2. 1-24 hours",IF(G24<=72,"3. 1-3 days","4. Over 3 days"))) | O24: =TEXT(B24,"YYYY-MM")
A25: LD-300023 | B25: 2025-01-30 18:27:00 | C25: Webinar | D25: Study Abroad Prep | E25: International | F25: Rep_10 | G25: 7.24 | H25: Contacted | I25: Open | M25: =VLOOKUP(H25,'Stage Order'!$A$2:$B$8,2,FALSE) | N25: =IF(G25<=1,"1. Under 1 hour",IF(G25<=24,"2. 1-24 hours",IF(G25<=72,"3. 1-3 days","4. Over 3 days"))) | O25: =TEXT(B25,"YYYY-MM")
A26: LD-300024 | B26: 2025-04-18 09:52:00 | C26: Webinar | D26: Language Learning | E26: South Region | F26: Rep_12 | G26: 2.76 | H26: Contacted | I26: Open | M26: =VLOOKUP(H26,'Stage Order'!$A$2:$B$8,2,FALSE) | N26: =IF(G26<=1,"1. Under 1 hour",IF(G26<=24,"2. 1-24 hours",IF(G26<=72,"3. 1-3 days","4. Over 3 days"))) | O26: =TEXT(B26,"YYYY-MM")
A27: LD-300025 | B27: 2025-08-25 14:06:00 | C27: Social Media | D27: Language Learning | E27: South Region | F27: Rep_07 | G27: 6.56 | H27: Lead | I27: Open | M27: =VLOOKUP(H27,'Stage Order'!$A$2:$B$8,2,FALSE) | N27: =IF(G27<=1,"1. Under 1 hour",IF(G27<=24,"2. 1-24 hours",IF(G27<=72,"3. 1-3 days","4. Over 3 days"))) | O27: =TEXT(B27,"YYYY-MM")
A28: LD-300026 | B28: 2025-07-18 12:47:00 | C28: Webinar | D28: Study Abroad Prep | E28: North Region | F28: Rep_01 | G28: 1.39 | H28: Demo Scheduled | I28: Open | M28: =VLOOKUP(H28,'Stage Order'!$A$2:$B$8,2,FALSE) | N28: =IF(G28<=1,"1. Under 1 hour",IF(G28<=24,"2. 1-24 hours",IF(G28<=72,"3. 1-3 days","4. Over 3 days"))) | O28: =TEXT(B28,"YYYY-MM")
A29: LD-300027 | B29: 2025-02-28 08:10:00 | C29: Social Media | D29: Competitive Exam Prep | E29: East Region | F29: Rep_04 | G29: 1.33 | H29: Lead | I29: Open | M29: =VLOOKUP(H29,'Stage Order'!$A$2:$B$8,2,FALSE) | N29: =IF(G29<=1,"1. Under 1 hour",IF(G29<=24,"2. 1-24 hours",IF(G29<=72,"3. 1-3 days","4. Over 3 days"))) | O29: =TEXT(B29,"YYYY-MM")
A30: LD-300028 | B30: 2026-02-13 10:50:00 | C30: Social Media | D30: K-12 Math | E30: South Region | F30: Rep_12 | G30: 1.08 | H30: Demo Scheduled | I30: Open | M30: =VLOOKUP(H30,'Stage Order'!$A$2:$B$8,2,FALSE) | N30: =IF(G30<=1,"1. Under 1 hour",IF(G30<=24,"2. 1-24 hours",IF(G30<=72,"3. 1-3 days","4. Over 3 days"))) | O30: =TEXT(B30,"YYYY-MM")
A31: LD-300029 | B31: 2025-05-16 19:39:00 | C31: Paid Search | D31: K-12 Math | E31: North Region | F31: Rep_01 | G31: 3.12 | H31: Contacted | I31: Open | M31: =VLOOKUP(H31,'Stage Order'!$A$2:$B$8,2,FALSE) | N31: =IF(G31<=1,"1. Under 1 hour",IF(G31<=24,"2. 1-24 hours",IF(G31<=72,"3. 1-3 days","4. Over 3 days"))) | O31: =TEXT(B31,"YYYY-MM")
A32: LD-300030 | B32: 2025-11-27 13:56:00 | C32: Referral | D32: K-12 Math | E32: West Region | F32: Rep_03 | G32: 4.02 | H32: Negotiation | I32: Lost | J32: Price Objection | K32: 447.9 | L32: 2026-01-24 08:30:40.903513 | M32: =VLOOKUP(H32,'Stage Order'!$A$2:$B$8,2,FALSE) | N32: =IF(G32<=1,"1. Under 1 hour",IF(G32<=24,"2. 1-24 hours",IF(G32<=72,"3. 1-3 days","4. Over 3 days"))) | O32: =TEXT(B32,"YYYY-MM")
A33: LD-300031 | B33: 2026-02-06 14:26:00 | C33: Cold Outreach | D33: K-12 Math | E33: South Region | F33: Rep_07 | G33: 22.8 | H33: Contacted | I33: Open | M33: =VLOOKUP(H33,'Stage Order'!$A$2:$B$8,2,FALSE) | N33: =IF(G33<=1,"1. Under 1 hour",IF(G33<=24,"2. 1-24 hours",IF(G33<=72,"3. 1-3 days","4. Over 3 days"))) | O33: =TEXT(B33,"YYYY-MM")
A34: LD-300032 | B34: 2026-04-12 19:06:00 | C34: Webinar | D34: Coding for Kids | E34: East Region | F34: Rep_14 | G34: 8.48 | H34: Proposal Sent | I34: Lost | J34: Price Objection | K34: 549.71 | L34: 2026-05-23 18:53:38.125827 | M34: =VLOOKUP(H34,'Stage Order'!$A$2:$B$8,2,FALSE) | N34: =IF(G34<=1,"1. Under 1 hour",IF(G34<=24,"2. 1-24 hours",IF(G34<=72,"3. 1-3 days","4. Over 3 days"))) | O34: =TEXT(B34,"YYYY-MM")
A35: LD-300033 | B35: 2025-04-03 20:22:00 | C35: Webinar | D35: Competitive Exam Prep | E35: East Region | F35: Rep_09 | G35: 7.92 | H35: Negotiation | I35: Lost | J35: Price Objection | K35: 813.36 | L35: 2025-05-31 22:08:19.446724 | M35: =VLOOKUP(H35,'Stage Order'!$A$2:$B$8,2,FALSE) | N35: =IF(G35<=1,"1. Under 1 hour",IF(G35<=24,"2. 1-24 hours",IF(G35<=72,"3. 1-3 days","4. Over 3 days"))) | O35: =TEXT(B35,"YYYY-MM")
A36: LD-300034 | B36: 2025-12-24 20:45:00 | C36: Paid Search | D36: Language Learning | E36: West Region | F36: Rep_08 | G36: 6.48 | H36: Contacted | I36: Open | M36: =VLOOKUP(H36,'Stage Order'!$A$2:$B$8,2,FALSE) | N36: =IF(G36<=1,"1. Under 1 hour",IF(G36<=24,"2. 1-24 hours",IF(G36<=72,"3. 1-3 days","4. Over 3 days"))) | O36: =TEXT(B36,"YYYY-MM")
A37: LD-300035 | B37: 2025-01-20 20:37:00 | C37: Social Media | D37: Coding for Kids | E37: West Region | F37: Rep_03 | G37: 1.46 | H37: Demo Completed | I37: Lost | J37: No Response / Ghosted | K37: 727.15 | L37: 2025-02-21 23:44:22.327292 | M37: =VLOOKUP(H37,'Stage Order'!$A$2:$B$8,2,FALSE) | N37: =IF(G37<=1,"1. Under 1 hour",IF(G37<=24,"2. 1-24 hours",IF(G37<=72,"3. 1-3 days","4. Over 3 days"))) | O37: =TEXT(B37,"YYYY-MM")
A38: LD-300036 | B38: 2025-03-25 13:49:00 | C38: Webinar | D38: Coding for Kids | E38: West Region | F38: Rep_08 | G38: 1.36 | H38: Negotiation | I38: Lost | J38: No Response / Ghosted | K38: 703.8 | L38: 2025-05-04 10:39:20.298738 | M38: =VLOOKUP(H38,'Stage Order'!$A$2:$B$8,2,FALSE) | N38: =IF(G38<=1,"1. Under 1 hour",IF(G38<=24,"2. 1-24 hours",IF(G38<=72,"3. 1-3 days","4. Over 3 days"))) | O38: =TEXT(B38,"YYYY-MM")
A39: LD-300037 | B39: 2026-05-04 07:42:00 | C39: Cold Outreach | D39: Coding for Kids | E39: West Region | F39: Rep_08 | G39: 1.37 | H39: Lead | I39: Open | M39: =VLOOKUP(H39,'Stage Order'!$A$2:$B$8,2,FALSE) | N39: =IF(G39<=1,"1. Under 1 hour",IF(G39<=24,"2. 1-24 hours",IF(G39<=72,"3. 1-3 days","4. Over 3 days"))) | O39: =TEXT(B39,"YYYY-MM")
A40: LD-300038 | B40: 2025-05-16 15:22:00 | C40: Paid Search | D40: Competitive Exam Prep | E40: South Region | F40: Rep_07 | G40: 1.25 | H40: Contacted | I40: Open | M40: =VLOOKUP(H40,'Stage Order'!$A$2:$B$8,2,FALSE) | N40: =IF(G40<=1,"1. Under 1 hour",IF(G40<=24,"2. 1-24 hours",IF(G40<=72,"3. 1-3 days","4. Over 3 days"))) | O40: =TEXT(B40,"YYYY-MM")
...

Sheet Stage Order
A1: stage_name | B1: stage_num
A2: Lead | B2: 1
A3: Contacted | B3: 2
A4: Demo Scheduled | B4: 3
A5: Demo Completed | B5: 4
A6: Proposal Sent | B6: 5
A7: Negotiation | B7: 6
A8: Closed | B8: 7

Sheet Funnel
A1: stage | B1: stage_num | C1: leads_reaching_or_beyond | D1: pct_of_total
A2: Lead | B2: 1 | C2: =COUNTIF(Data!$M$2:$M$7001,">="&B2) | D2: =ROUND(C2/COUNTA(Data!$A$2:$A$7001)*100,1)
A3: Contacted | B3: 2 | C3: =COUNTIF(Data!$M$2:$M$7001,">="&B3) | D3: =ROUND(C3/COUNTA(Data!$A$2:$A$7001)*100,1)
A4: Demo Scheduled | B4: 3 | C4: =COUNTIF(Data!$M$2:$M$7001,">="&B4) | D4: =ROUND(C4/COUNTA(Data!$A$2:$A$7001)*100,1)
A5: Demo Completed | B5: 4 | C5: =COUNTIF(Data!$M$2:$M$7001,">="&B5) | D5: =ROUND(C5/COUNTA(Data!$A$2:$A$7001)*100,1)
A6: Proposal Sent | B6: 5 | C6: =COUNTIF(Data!$M$2:$M$7001,">="&B6) | D6: =ROUND(C6/COUNTA(Data!$A$2:$A$7001)*100,1)
A7: Negotiation | B7: 6 | C7: =COUNTIF(Data!$M$2:$M$7001,">="&B7) | D7: =ROUND(C7/COUNTA(Data!$A$2:$A$7001)*100,1)
A8: Closed | B8: 7 | C8: =COUNTIF(Data!$M$2:$M$7001,">="&B8) | D8: =ROUND(C8/COUNTA(Data!$A$2:$A$7001)*100,1)

Sheet Win Rate by Source
A1: source | B1: total_leads | C1: won | D1: win_rate_pct
A2: Cold Outreach | B2: =COUNTIF(Data!$C$2:$C$7001,A2) | C2: =COUNTIFS(Data!$C$2:$C$7001,A2,Data!$I$2:$I$7001,"Won") | D2: =ROUND(C2/B2*100,1)
A3: Organic Search | B3: =COUNTIF(Data!$C$2:$C$7001,A3) | C3: =COUNTIFS(Data!$C$2:$C$7001,A3,Data!$I$2:$I$7001,"Won") | D3: =ROUND(C3/B3*100,1)
A4: Paid Search | B4: =COUNTIF(Data!$C$2:$C$7001,A4) | C4: =COUNTIFS(Data!$C$2:$C$7001,A4,Data!$I$2:$I$7001,"Won") | D4: =ROUND(C4/B4*100,1)
A5: Partner Channel | B5: =COUNTIF(Data!$C$2:$C$7001,A5) | C5: =COUNTIFS(Data!$C$2:$C$7001,A5,Data!$I$2:$I$7001,"Won") | D5: =ROUND(C5/B5*100,1)
A6: Referral | B6: =COUNTIF(Data!$C$2:$C$7001,A6) | C6: =COUNTIFS(Data!$C$2:$C$7001,A6,Data!$I$2:$I$7001,"Won") | D6: =ROUND(C6/B6*100,1)
A7: Social Media | B7: =COUNTIF(Data!$C$2:$C$7001,A7) | C7: =COUNTIFS(Data!$C$2:$C$7001,A7,Data!$I$2:$I$7001,"Won") | D7: =ROUND(C7/B7*100,1)
A8: Webinar | B8: =COUNTIF(Data!$C$2:$C$7001,A8) | C8: =COUNTIFS(Data!$C$2:$C$7001,A8,Data!$I$2:$I$7001,"Won") | D8: =ROUND(C8/B8*100,1)

Sheet Speed to Lead
A1: response_bucket | B1: total_leads | C1: won | D1: win_rate_pct
A2: 1. Under 1 hour | B2: =COUNTIF(Data!$N$2:$N$7001,A2) | C2: =COUNTIFS(Data!$N$2:$N$7001,A2,Data!$I$2:$I$7001,"Won") | D2: =ROUND(C2/B2*100,1)
A3: 2. 1-24 hours | B3: =COUNTIF(Data!$N$2:$N$7001,A3) | C3: =COUNTIFS(Data!$N$2:$N$7001,A3,Data!$I$2:$I$7001,"Won") | D3: =ROUND(C3/B3*100,1)
A4: 3. 1-3 days | B4: =COUNTIF(Data!$N$2:$N$7001,A4) | C4: =COUNTIFS(Data!$N$2:$N$7001,A4,Data!$I$2:$I$7001,"Won") | D4: =ROUND(C4/B4*100,1)
A5: 4. Over 3 days | B5: =COUNTIF(Data!$N$2:$N$7001,A5) | C5: =COUNTIFS(Data!$N$2:$N$7001,A5,Data!$I$2:$I$7001,"Won") | D5: =ROUND(C5/B5*100,1)

Sheet Lost Value by Reason
A1: lost_reason | B1: lost_deals | C1: total_lost_value | D1: avg_lost_value
A2: Bad Timing | B2: =COUNTIFS(Data!$I$2:$I$7001,"Lost",Data!$J$2:$J$7001,A2) | C2: =ROUND(SUMIFS(Data!$K$2:$K$7001,Data!$I$2:$I$7001,"Lost",Data!$J$2:$J$7001,A2),2) | D2: =ROUND(AVERAGEIFS(Data!$K$2:$K$7001,Data!$I$2:$I$7001,"Lost",Data!$J$2:$J$7001,A2),2)
A3: Budget Not Approved | B3: =COUNTIFS(Data!$I$2:$I$7001,"Lost",Data!$J$2:$J$7001,A3) | C3: =ROUND(SUMIFS(Data!$K$2:$K$7001,Data!$I$2:$I$7001,"Lost",Data!$J$2:$J$7001,A3),2) | D3: =ROUND(AVERAGEIFS(Data!$K$2:$K$7001,Data!$I$2:$I$7001,"Lost",Data!$J$2:$J$7001,A3),2)
A4: No Response / Ghosted | B4: =COUNTIFS(Data!$I$2:$I$7001,"Lost",Data!$J$2:$J$7001,A4) | C4: =ROUND(SUMIFS(Data!$K$2:$K$7001,Data!$I$2:$I$7001,"Lost",Data!$J$2:$J$7001,A4),2) | D4: =ROUND(AVERAGEIFS(Data!$K$2:$K$7001,Data!$I$2:$I$7001,"Lost",Data!$J$2:$J$7001,A4),2)
A5: Price Objection | B5: =COUNTIFS(Data!$I$2:$I$7001,"Lost",Data!$J$2:$J$7001,A5) | C5: =ROUND(SUMIFS(Data!$K$2:$K$7001,Data!$I$2:$I$7001,"Lost",Data!$J$2:$J$7001,A5),2) | D5: =ROUND(AVERAGEIFS(Data!$K$2:$K$7001,Data!$I$2:$I$7001,"Lost",Data!$J$2:$J$7001,A5),2)
A6: Went With Competitor | B6: =COUNTIFS(Data!$I$2:$I$7001,"Lost",Data!$J$2:$J$7001,A6) | C6: =ROUND(SUMIFS(Data!$K$2:$K$7001,Data!$I$2:$I$7001,"Lost",Data!$J$2:$J$7001,A6),2) | D6: =ROUND(AVERAGEIFS(Data!$K$2:$K$7001,Data!$I$2:$I$7001,"Lost",Data!$J$2:$J$7001,A6),2)

Sheet Rep Leaderboard
A1: rep | B1: total_leads | C1: won | D1: win_rate_pct | E1: total_revenue
A2: Rep_01 | B2: =COUNTIF(Data!$F$2:$F$7001,A2) | C2: =COUNTIFS(Data!$F$2:$F$7001,A2,Data!$I$2:$I$7001,"Won") | D2: =ROUND(C2/B2*100,1) | E2: =ROUND(SUMIFS(Data!$K$2:$K$7001,Data!$F$2:$F$7001,A2,Data!$I$2:$I$7001,"Won"),2)
A3: Rep_02 | B3: =COUNTIF(Data!$F$2:$F$7001,A3) | C3: =COUNTIFS(Data!$F$2:$F$7001,A3,Data!$I$2:$I$7001,"Won") | D3: =ROUND(C3/B3*100,1) | E3: =ROUND(SUMIFS(Data!$K$2:$K$7001,Data!$F$2:$F$7001,A3,Data!$I$2:$I$7001,"Won"),2)
A4: Rep_03 | B4: =COUNTIF(Data!$F$2:$F$7001,A4) | C4: =COUNTIFS(Data!$F$2:$F$7001,A4,Data!$I$2:$I$7001,"Won") | D4: =ROUND(C4/B4*100,1) | E4: =ROUND(SUMIFS(Data!$K$2:$K$7001,Data!$F$2:$F$7001,A4,Data!$I$2:$I$7001,"Won"),2)
A5: Rep_04 | B5: =COUNTIF(Data!$F$2:$F$7001,A5) | C5: =COUNTIFS(Data!$F$2:$F$7001,A5,Data!$I$2:$I$7001,"Won") | D5: =ROUND(C5/B5*100,1) | E5: =ROUND(SUMIFS(Data!$K$2:$K$7001,Data!$F$2:$F$7001,A5,Data!$I$2:$I$7001,"Won"),2)
A6: Rep_05 | B6: =COUNTIF(Data!$F$2:$F$7001,A6) | C6: =COUNTIFS(Data!$F$2:$F$7001,A6,Data!$I$2:$I$7001,"Won") | D6: =ROUND(C6/B6*100,1) | E6: =ROUND(SUMIFS(Data!$K$2:$K$7001,Data!$F$2:$F$7001,A6,Data!$I$2:$I$7001,"Won"),2)
A7: Rep_06 | B7: =COUNTIF(Data!$F$2:$F$7001,A7) | C7: =COUNTIFS(Data!$F$2:$F$7001,A7,Data!$I$2:$I$7001,"Won") | D7: =ROUND(C7/B7*100,1) | E7: =ROUND(SUMIFS(Data!$K$2:$K$7001,Data!$F$2:$F$7001,A7,Data!$I$2:$I$7001,"Won"),2)
A8: Rep_07 | B8: =COUNTIF(Data!$F$2:$F$7001,A8) | C8: =COUNTIFS(Data!$F$2:$F$7001,A8,Data!$I$2:$I$7001,"Won") | D8: =ROUND(C8/B8*100,1) | E8: =ROUND(SUMIFS(Data!$K$2:$K$7001,Data!$F$2:$F$7001,A8,Data!$I$2:$I$7001,"Won"),2)
A9: Rep_08 | B9: =COUNTIF(Data!$F$2:$F$7001,A9) | C9: =COUNTIFS(Data!$F$2:$F$7001,A9,Data!$I$2:$I$7001,"Won") | D9: =ROUND(C9/B9*100,1) | E9: =ROUND(SUMIFS(Data!$K$2:$K$7001,Data!$F$2:$F$7001,A9,Data!$I$2:$I$7001,"Won"),2)
A10: Rep_09 | B10: =COUNTIF(Data!$F$2:$F$7001,A10) | C10: =COUNTIFS(Data!$F$2:$F$7001,A10,Data!$I$2:$I$7001,"Won") | D10: =ROUND(C10/B10*100,1) | E10: =ROUND(SUMIFS(Data!$K$2:$K$7001,Data!$F$2:$F$7001,A10,Data!$I$2:$I$7001,"Won"),2)
A11: Rep_10 | B11: =COUNTIF(Data!$F$2:$F$7001,A11) | C11: =COUNTIFS(Data!$F$2:$F$7001,A11,Data!$I$2:$I$7001,"Won") | D11: =ROUND(C11/B11*100,1) | E11: =ROUND(SUMIFS(Data!$K$2:$K$7001,Data!$F$2:$F$7001,A11,Data!$I$2:$I$7001,"Won"),2)
A12: Rep_11 | B12: =COUNTIF(Data!$F$2:$F$7001,A12) | C12: =COUNTIFS(Data!$F$2:$F$7001,A12,Data!$I$2:$I$7001,"Won") | D12: =ROUND(C12/B12*100,1) | E12: =ROUND(SUMIFS(Data!$K$2:$K$7001,Data!$F$2:$F$7001,A12,Data!$I$2:$I$7001,"Won"),2)
A13: Rep_12 | B13: =COUNTIF(Data!$F$2:$F$7001,A13) | C13: =COUNTIFS(Data!$F$2:$F$7001,A13,Data!$I$2:$I$7001,"Won") | D13: =ROUND(C13/B13*100,1) | E13: =ROUND(SUMIFS(Data!$K$2:$K$7001,Data!$F$2:$F$7001,A13,Data!$I$2:$I$7001,"Won"),2)
... A16: Rep_15 | B16: =COUNTIF(Data!$F$2:$F$7001,A16) | C16: =COUNTIFS(Data!$F$2:$F$7001,A16,Data!$I$2:$I$7001,"Won") | D16: =ROUND(C16/B16*100,1) | E16: =ROUND(SUMIFS(Data!$K$2:$K$7001,Data!$F$2:$F$7001,A16,Data!$I$2:$I$7001,"Won"),2)

Sheet Monthly Trend
A1: month | B1: leads | C1: win_rate_pct
A2: 2025-01 | B2: =COUNTIF(Data!$O$2:$O$7001,A2) | C2: =ROUND(COUNTIFS(Data!$O$2:$O$7001,A2,Data!$I$2:$I$7001,"Won")/B2*100,1)
A3: 2025-02 | B3: =COUNTIF(Data!$O$2:$O$7001,A3) | C3: =ROUND(COUNTIFS(Data!$O$2:$O$7001,A3,Data!$I$2:$I$7001,"Won")/B3*100,1)
A4: 2025-03 | B4: =COUNTIF(Data!$O$2:$O$7001,A4) | C4: =ROUND(COUNTIFS(Data!$O$2:$O$7001,A4,Data!$I$2:$I$7001,"Won")/B4*100,1)
A5: 2025-04 | B5: =COUNTIF(Data!$O$2:$O$7001,A5) | C5: =ROUND(COUNTIFS(Data!$O$2:$O$7001,A5,Data!$I$2:$I$7001,"Won")/B5*100,1)
A6: 2025-05 | B6: =COUNTIF(Data!$O$2:$O$7001,A6) | C6: =ROUND(COUNTIFS(Data!$O$2:$O$7001,A6,Data!$I$2:$I$7001,"Won")/B6*100,1)
A7: 2025-06 | B7: =COUNTIF(Data!$O$2:$O$7001,A7) | C7: =ROUND(COUNTIFS(Data!$O$2:$O$7001,A7,Data!$I$2:$I$7001,"Won")/B7*100,1)
A8: 2025-07 | B8: =COUNTIF(Data!$O$2:$O$7001,A8) | C8: =ROUND(COUNTIFS(Data!$O$2:$O$7001,A8,Data!$I$2:$I$7001,"Won")/B8*100,1)
A9: 2025-08 | B9: =COUNTIF(Data!$O$2:$O$7001,A9) | C9: =ROUND(COUNTIFS(Data!$O$2:$O$7001,A9,Data!$I$2:$I$7001,"Won")/B9*100,1)
A10: 2025-09 | B10: =COUNTIF(Data!$O$2:$O$7001,A10) | C10: =ROUND(COUNTIFS(Data!$O$2:$O$7001,A10,Data!$I$2:$I$7001,"Won")/B10*100,1)
A11: 2025-10 | B11: =COUNTIF(Data!$O$2:$O$7001,A11) | C11: =ROUND(COUNTIFS(Data!$O$2:$O$7001,A11,Data!$I$2:$I$7001,"Won")/B11*100,1)
A12: 2025-11 | B12: =COUNTIF(Data!$O$2:$O$7001,A12) | C12: =ROUND(COUNTIFS(Data!$O$2:$O$7001,A12,Data!$I$2:$I$7001,"Won")/B12*100,1)
A13: 2025-12 | B13: =COUNTIF(Data!$O$2:$O$7001,A13) | C13: =ROUND(COUNTIFS(Data!$O$2:$O$7001,A13,Data!$I$2:$I$7001,"Won")/B13*100,1)
... A19: 2026-06 | B19: =COUNTIF(Data!$O$2:$O$7001,A19) | C19: =ROUND(COUNTIFS(Data!$O$2:$O$7001,A19,Data!$I$2:$I$7001,"Won")/B19*100,1)
